<?xml version="1.0" ?>
<robot name="gripper">
  <link name="baseLink">
    <inertial>
      <origin rpy="0 0 0" xyz="0 0 0"/>
       <mass value="0.001"/>
       <inertia ixx="0.01" ixy="0" ixz="0" iyy="0.01" iyz="0" izz="0.01"/>
    </inertial>
    <visual>
      <origin rpy="0 0 0" xyz="0 0.0 0.075"/>
      <geometry>
			<box size="0.3 0.15 0.15"/>
      </geometry>
       <material name="grey">
        <color rgba="0.5 0.5 0.5 1.0"/>
      </material>
    </visual>
    <collision>
      <origin rpy="0 0 0" xyz="0 0.0 0.075"/>
      <geometry>
			<box size="0.3 0.15 0.15"/>
      </geometry>
    </collision>
  </link>
  <link name="leftfinger">
      <contact>
      <friction_anchor/>
      <stiffness value="30000.0"/>
      <damping value="1000.0"/>
      <spinning_friction value="0.75"/>
      <lateral_friction value="1.0"/>
    </contact>
  	<inertial>
      <origin rpy="0 0 0" xyz="0 0 0"/>
       <mass value="0.1"/>
       <inertia ixx="0.1" ixy="0" ixz="0" iyy="0.1" iyz="0" izz="0.1"/>
    </inertial>
    <visual>
      <origin rpy="0 0 0" xyz="0.0 0.0 0.1"/>
      <geometry>
        <cylinder radius="0.025" length="0.2"/>
      </geometry>
    </visual>
    <collision>
      <origin rpy="0 0 0" xyz="0.0 0 0.1"/>
      <geometry>
        <cylinder radius="0.025" length="0.2"/>
      </geometry>
      <material name="white"/>
    </collision>
  </link>
  <link name="rightfinger">
      <contact>
      <friction_anchor/>
      <stiffness value="30000.0"/>
      <damping value="1000.0"/>
      <spinning_friction value="0.75"/>
      <lateral_friction value="1.0"/>
    </contact>
  	<inertial>
      <origin rpy="0 0 0" xyz="0 0 0"/>
       <mass value="0.1"/>
       <inertia ixx="0.1" ixy="0" ixz="0" iyy="0.1" iyz="0" izz="0.1"/>
    </inertial>
      <geometry>
		<box size="0.2 0.05 0.05"/>
      </geometry>
      <material name="white"/>
    <visual>
      <origin rpy="0 0 0" xyz="0.0 0.0 0.1"/>
      <geometry>
        <cylinder radius="0.025" length="0.2"/>
      </geometry>
    </visual>
    <collision>
      <origin rpy="0 0 0" xyz="0.0 0 0.1"/>
      <geometry>
        <cylinder radius="0.025" length="0.2"/>
      </geometry>
      <material name="white"/>
    </collision>
  </link>
  <joint name="finger_joint1" type="prismatic">
    <parent link="baseLink"/>
    <child link="leftfinger"/>
    <origin rpy="0 0 0" xyz="0.15 0 0.15"/>
    <axis xyz="-1 0 0"/>
    <limit effort="200" lower="0.0" upper="0.11" velocity="0.2"/>
  </joint>
  <joint name="finger_joint2" type="prismatic">
    <parent link="baseLink"/>
    <child link="rightfinger"/>
    <origin rpy="0 0 0" xyz="-0.15 0 0.15"/>
    <axis xyz="1 0 0"/>
    <limit effort="200" lower="-0" upper="0.11" velocity="0.2"/>
    <mimic joint="finger_joint1"/>
  </joint>

  <joint name="gripping_trafo" type="fixed">
		<parent link="baseLink"/>
		<child link="tcp"/>
		<origin xyz="0 0.0 0.25" rpy="0 0 0"/>
  </joint>

  <link name="tcp">

  </link>

</robot>
