<?xml version="1.0" ?>
<robot name="gripper">
  <link name="baseLink">
    <inertial>
      <origin rpy="0 0 0" xyz="0 0 0"/>
       <mass value="0.001"/>
       <inertia ixx="0.01" ixy="0" ixz="0" iyy="0.01" iyz="0" izz="0.01"/>
    </inertial>
    <visual>
      <origin rpy="0 0 0" xyz="0 0.0 0.0"/>
      <geometry>
			<mesh filename="tool_mesh/base_m.stl"/>
      </geometry>
       <material name="grey">
        <color rgba="0.5 0.5 0.5 1.0"/>
      </material>
    </visual>
  </link>
  <link name="leftfinger">
      <contact>
      <friction_anchor/>
      <stiffness value="30000.0"/>
      <damping value="1000.0"/>
      <spinning_friction value="0.1"/>
      <lateral_friction value="3.0"/>
      <contact_cfm value="0.2"/>
    </contact>
  	<inertial>
      <origin rpy="0 0 0" xyz="0 0 0"/>
       <mass value="0.1"/>
       <inertia ixx="0.1" ixy="0" ixz="0" iyy="0.1" iyz="0" izz="0.1"/>
    </inertial>
    <visual>
      <origin rpy="0 0 0" xyz="0 0.0 0.0"/>
      <geometry>
			<mesh filename="tool_mesh/finger01_m.stl"/>
      </geometry>
    </visual>
    <collision>
      <origin rpy="0 0 0" xyz="0 0.0 0.0"/>
      <geometry>
			<mesh filename="tool_mesh/finger01_m.stl"/>
      </geometry>
      <material name="white"/>
    </collision>
  </link>
  <link name="rightfinger">
      <contact>
      <friction_anchor/>
      <stiffness value="30000.0"/>
      <damping value="1000.0"/>
      <spinning_friction value="0.1"/>
      <lateral_friction value="3.0"/>
      <contact_cfm value="0.2"/>
    </contact>
  	<inertial>
      <origin rpy="0 0 0" xyz="0 0 0"/>
       <mass value="0.1"/>
       <inertia ixx="0.1" ixy="0" ixz="0" iyy="0.1" iyz="0" izz="0.1"/>
    </inertial>
    <visual>
      <origin rpy="0 0 0" xyz="0 0.0 0.0"/>
      <geometry>
			<mesh filename="tool_mesh/finger02_m.stl"/>
      </geometry>
    </visual>
    <collision>
      <origin rpy="0 0 0" xyz="0 0.0 0.0"/>
      <geometry>
			<mesh filename="tool_mesh/finger02_m.stl"/>
      </geometry>
      <material name="white"/>
    </collision>
  </link>
  <joint name="finger_joint1" type="prismatic">
    <parent link="baseLink"/>
    <child link="leftfinger"/>
    <origin rpy="0 0 0" xyz="0.0 0 0.0"/>
    <axis xyz="-1 0 0"/>
    <limit effort="20" lower="-0.05" upper="0.11" velocity="0.2"/>
  </joint>
  <joint name="finger_joint2" type="prismatic">
    <parent link="baseLink"/>
    <child link="rightfinger"/>
    <origin rpy="0 0 0" xyz="0.0 0 0.0"/>
    <axis xyz="1 0 0"/>
    <limit effort="20" lower="-0.05" upper="0.11" velocity="0.2"/>
    <mimic joint="finger_joint1"/>
  </joint>

  <joint name="gripping_trafo" type="fixed">
		<parent link="baseLink"/>
		<child link="tcp"/>
		<origin xyz="0 0.0 0.39" rpy="0 0 0"/>
  </joint>

  <link name="tcp">

  </link>

</robot>
