<?xml version="1.0" encoding="utf-8"?>
<!-- This URDF was automatically created by SolidWorks to URDF Exporter! Originally created by Stephen Brawner (brawner@gmail.com)
     Commit Version: 1.6.0-4-g7f85cfe  Build Version: 1.6.7995.38578
     For more information, please see http://wiki.ros.org/sw_urdf_exporter -->
<robot
  name="scara_control">

  <link
    name="base_link">
    <inertial>
      <origin
        xyz="0.11871 -0.00024099 0.13313"
        rpy="0 0 0" />
      <mass
        value="2.7892" />
      <inertia
        ixx="0.00938"
        ixy="2.8187E-06"
        ixz="0.00077715"
        iyy="0.015372"
        iyz="3.7411E-05"
        izz="0.010695" />
    </inertial>
    <visual>
      <origin
        xyz="0 0 0"
        rpy="0 0 0" />
      <geometry>
        <mesh
          filename="scara_meshes/base_link.STL" />
      </geometry>
      <material
        name="aluminium 6061 T6">
        <color
          rgba="1 1 1 0.4" />
      </material>
    </visual>
    <collision>
      <origin
        xyz="0 0 0"
        rpy="0 0 0" />
      <geometry>
        <mesh
          filename="scara_meshes/base_link.STL" />
      </geometry>
    </collision>
  </link>

  <joint
    name="joint_1"
    type="revolute">
    <origin
      xyz="0.065 0 0"
      rpy="0 0 0" />
    <parent
      link="base_link" />
    <child
      link="link_1" />
    <axis
      xyz="0 0 1" />
    <limit
      lower="-3.28"
      upper="-0.20"
      effort="300"
      velocity="2.53" />
  </joint>

  <link
    name="link_1">
    <inertial>
      <origin
        xyz="0.013522 -0.078455 0.17948"
        rpy="0 0 0" />
      <mass
        value="0.78816" />
      <inertia
        ixx="0.0041756"
        ixy="0.00055425"
        ixz="-3.355E-05"
        iyy="0.0010607"
        iyz="0.0001927"
        izz="0.0040706" />
    </inertial>
    <visual>
      <origin
        xyz="0 0 0"
        rpy="0 0 0" />
      <geometry>
        <mesh
          filename="scara_meshes/link_1.STL" />
      </geometry>
      <material
        name="">
        <color
          rgba="0.89804 0.91765 0.92941 1" />
      </material>
    </visual>
    <collision>
      <origin
        xyz="0 0 0"
        rpy="0 0 0" />
      <geometry>
        <mesh
          filename="scara_meshes/link_1.STL" />
      </geometry>
    </collision>
  </link>

  <joint
    name="joint_2"
    type="revolute">
    <origin
      xyz="0.028115 -0.16259 0.2335"
      rpy="0 0 0" />
    <parent
      link="link_1" />
    <child
      link="link_2" />
    <axis
      xyz="0 0 1" />
    <limit
      lower="-2.68"
      upper="0.79"
      effort="200"
      velocity="2.53" />
  </joint>

  <link
    name="link_2">
    <inertial>
      <origin
        xyz="0.0463351759195657 -0.0200608690825873 0.021118139203296"
        rpy="0 0 0" />
      <mass
        value="0.602617398624407" />
      <inertia
        ixx="0.00099209316442581"
        ixy="0.000506296868083949"
        ixz="-0.000102941793901956"
        iyy="0.00178396270811336"
        iyz="5.61514870728229E-05"
        izz="0.00181833324438623" />
    </inertial>
    <visual>
      <origin
        xyz="0 0 0"
        rpy="0 0 0" />
      <geometry>
        <mesh
          filename="scara_meshes/link_2.STL" />
      </geometry>
      <material
        name="">
        <color
          rgba="0.898039215686275 0.917647058823529 0.929411764705882 1" />
      </material>
    </visual>
    <collision>
      <origin
        xyz="0 0 0"
        rpy="0 0 0" />
      <geometry>
        <mesh
          filename="scara_meshes/link_2.STL" />
      </geometry>
    </collision>
  </link>

  <joint
    name="joint_3"
    type="prismatic">
    <origin
      xyz="0.10838 -0.062931 0.0386"
      rpy="0 0 0" />
    <parent
      link="link_2" />
    <child
      link="link_3" />
    <axis
      xyz="0 0 1" />
    <limit
      lower="-0.08"
      upper="0"
      effort="50"
      velocity="1" />
  </joint>

  <link
    name="link_3">
    <inertial>
      <origin
        xyz="-0.00278701904931913 0.0195492334375744 -0.0437473711092172"
        rpy="0 0 0" />
      <mass
        value="0.148684285758606" />
      <inertia
        ixx="0.000227356649505814"
        ixy="-5.14353541170312E-08"
        ixz="1.89190973787103E-06"
        iyy="0.000228324552451677"
        iyz="1.4987192171224E-06"
        izz="1.04559446013558E-05" />
    </inertial>
    <visual>
      <origin
        xyz="0 0 0"
        rpy="0 0 0" />
      <geometry>
        <mesh
          filename="scara_meshes/link_3.STL" />
      </geometry>
      <material
        name="">
        <color
          rgba="0.898039215686275 0.917647058823529 0.929411764705882 1" />
      </material>
    </visual>
    <collision>
      <origin
        xyz="0 0 0"
        rpy="0 0 0" />
      <geometry>
        <mesh
          filename="scara_meshes/link_3.STL" />
      </geometry>
    </collision>
  </link>

  <transmission name="trans_joint_1">
        <type>transmission_interface/SimpleTransmission</type>
        <joint name="joint_1">
            <hardwareInterface>hardware_interface/PositionJointInterface</hardwareInterface>
        </joint>
        <actuator name="joint_1_motor">
            <hardwareInterface>hardware_interface/PositionJointInterface</hardwareInterface>
            <mechanicalReduction>1</mechanicalReduction>
        </actuator>
    </transmission>
    <transmission name="trans_joint_2">
        <type>transmission_interface/SimpleTransmission</type>
        <joint name="joint_2">
            <hardwareInterface>hardware_interface/PositionJointInterface</hardwareInterface>
        </joint>
        <actuator name="joint_2_motor">
            <hardwareInterface>hardware_interface/PositionJointInterface</hardwareInterface>
            <mechanicalReduction>1</mechanicalReduction>
        </actuator>
    </transmission>
    <transmission name="trans_joint_3">
        <type>transmission_interface/SimpleTransmission</type>
        <joint name="joint_3">
            <hardwareInterface>hardware_interface/PositionJointInterface</hardwareInterface>
        </joint>
        <actuator name="joint_3_motor">
            <hardwareInterface>hardware_interface/PositionJointInterface</hardwareInterface>
            <mechanicalReduction>1</mechanicalReduction>
        </actuator>
    </transmission>

  <transmission name="trans_joint_1">
        <type>transmission_interface/SimpleTransmission</type>
        <joint name="joint_1">
            <hardwareInterface>hardware_interface/EffortJointInterface</hardwareInterface>
        </joint>
        <actuator name="joint_1_motor">
            <hardwareInterface>hardware_interface/EffortJointInterface</hardwareInterface>
            <mechanicalReduction>1</mechanicalReduction>
        </actuator>
    </transmission>
    <transmission name="trans_joint_2">
        <type>transmission_interface/SimpleTransmission</type>
        <joint name="joint_2">
            <hardwareInterface>hardware_interface/EffortJointInterface</hardwareInterface>
        </joint>
        <actuator name="joint_2_motor">
            <hardwareInterface>hardware_interface/EffortJointInterface</hardwareInterface>
            <mechanicalReduction>1</mechanicalReduction>
        </actuator>
    </transmission>
    <transmission name="trans_joint_3">
        <type>transmission_interface/SimpleTransmission</type>
        <joint name="joint_3">
            <hardwareInterface>hardware_interface/EffortJointInterface</hardwareInterface>
        </joint>
        <actuator name="joint_3_motor">
            <hardwareInterface>hardware_interface/EffortJointInterface</hardwareInterface>
            <mechanicalReduction>1</mechanicalReduction>
        </actuator>
    </transmission>

  <gazebo>
        <plugin name="gazebo_ros_control" filename="libgazebo_ros_control.so">
            <robotNamespace>/scara_control</robotNamespace>
        </plugin>
    </gazebo>
</robot>


