<?xml version="1.0" ?>
<robot name="SRG">
  <link name="baseLink">
  </link>
  <link name="body">
    <inertial>
      <origin rpy="0 0 0" xyz="0 0 0"/>
       <mass value="0.001"/>
       <inertia ixx="0.01" ixy="0" ixz="0" iyy="0.01" iyz="0" izz="0.01"/>
    </inertial>
    <visual>
      <origin rpy="0 0 0" xyz="0 0.0 0.0"/>
      <geometry>
			<mesh filename="tool_mesh/SRG_Base.stl" scale="0.001 0.001 0.001"/>
      </geometry>
       <material name="grey">
        <color rgba="0.5 0.5 0.5 1.0"/>
      </material>
    </visual>
    <collision>
      <origin rpy="0 0 0" xyz="0 0.0 0.0"/>
      <geometry>
			<mesh filename="tool_mesh/SRG_Base.stl" scale="0.001 0.001 0.001"/>
      </geometry>>
    </collision>
  </link>
  <link name="leftfinger">
    <contact>
      <stiffness value="1000.0"/>
      <damping value="10.0"/>
      <spinning_friction value="1"/>
      <lateral_friction value="1"/>
      <rolling_friction value="1" />
      <contact_cfm value="100"/>
      <contact_erp value="100"/>
    </contact>
  	<inertial>
      <origin rpy="0 0 0" xyz="0 0 0"/>
       <mass value="0.1"/>
       <inertia ixx="0.1" ixy="0" ixz="0" iyy="0.1" iyz="0" izz="0.1"/>
    </inertial>
    <visual>
      <origin rpy="0 0 0" xyz="0.0 0.0 0.0"/>
      <geometry>
			<mesh filename="tool_mesh/SRG_Finger1.stl" scale="0.001 0.001 0.001"/>
      </geometry>
    </visual>
    <collision>
      <origin rpy="0 0 0" xyz="0.0 0 0.0"/>
      <geometry>
			<mesh filename="tool_mesh/SRG_Finger1.stl" scale="0.001 0.001 0.001"/>
      </geometry>
      <material name="white"/>
    </collision>
  </link>
  <link name="rightfinger">
    <contact>
      <stiffness value="1000.0"/>
      <damping value="10.0"/>
      <spinning_friction value="1"/>
      <lateral_friction value="1"/>
      <rolling_friction value="1" />
      <contact_cfm value="100"/>
      <contact_erp value="100"/>
    </contact>
  	<inertial>
      <origin rpy="0 0 0" xyz="0 0 0"/>
       <mass value="0.1"/>
       <inertia ixx="0.1" ixy="0" ixz="0" iyy="0.1" iyz="0" izz="0.1"/>
    </inertial>
    <visual>
      <origin rpy="0 0 0" xyz="0.0 0.0 0.0"/>
      <geometry>
			<mesh filename="tool_mesh/SRG_Finger2.stl" scale="0.001 0.001 0.001"/>
      </geometry>
      <material name="white"/>
    </visual>
    <collision>
      <origin rpy="0 0 0" xyz="0.0 0.0 0.0"/>
      <geometry>
			<mesh filename="tool_mesh/SRG_Finger2.stl" scale="0.001 0.001 0.001"/>
      </geometry>
      <material name="white"/>
    </collision>
  </link>
  <joint name="docking_trafo" type="fixed">
		<parent link="baseLink"/>
		<child link="body"/>
		<origin rpy="0 0 0" xyz="0 0 0"/>
  </joint>
  <joint name="finger_joint1" type="prismatic">
    <parent link="body"/>
    <child link="leftfinger"/>
    <origin rpy="0 0 0" xyz="0 0 0"/>
    <axis xyz="0 -1 0"/>
    <limit effort="0.001" lower="-0.02" upper="0.0" velocity="0.2"/>
  </joint>
  <joint name="finger_joint2" type="prismatic">
    <parent link="body"/>
    <child link="rightfinger"/>
    <origin rpy="0 0 0" xyz="0 0 0"/>
    <axis xyz="0 1 0"/>
    <limit effort="0.001" lower="-0.02" upper="0.0" velocity="0.2"/>
    <mimic joint="finger_joint1"/>
  </joint>

  <joint name="gripping_trafo" type="fixed">
		<parent link="baseLink"/>
		<child link="tcp"/>
		<origin xyz="0.006 0.0 -0.245" rpy="0 0 0"/>
  </joint>

  <link name="tcp">
    <visual>
        <origin xyz="0 0 0.0" rpy="0 0 0"/>
        <geometry>
           <sphere radius="0.005"/>
        </geometry>
        <material name="black">
            <color rgba="0.0 0.5 0.0 1.0"/>
        </material>
    </visual>
  </link>

</robot>
